<?xml version="1.0" encoding="utf-8"?>
<!-- =================================================================================== -->
<!-- |    This document was autogenerated by xacro from spotmicroai.urdf.xacro         | -->
<!-- |    EDITING THIS FILE BY HAND IS NOT RECOMMENDED                                 | -->
<!-- =================================================================================== -->
<robot name="SpotMicroAI">
  <material name="yellow">
    <color rgba="0.92 0.83 0.0 1"/>
  </material>
  <material name="black">
    <color rgba="0.1 0.1 0.1 1"/>
  </material>
  <material name="grey">
    <color rgba="0.6 0.6 0.6 1"/>
  </material>
  <!-- Robot Body -->
  <link name="base_link"/>
  <link name="base_inertia">
    <visual>
      <geometry>
        <mesh filename="package://spotmicro_description/meshes/stl/mainbody.stl" scale="0.001 0.001 0.001"/>
      </geometry>
      <material name="black"/>
      <origin rpy="0 0 3.1416" xyz="0.0425 0.055 -0.02"/>
    </visual>
    <collision>
      <geometry>
        <box size="0.14 0.11 0.07"/>
      </geometry>
      <origin rpy="0 0 3.1416" xyz="0 0 0"/>
    </collision>
    <inertial>
      <origin rpy="0 0 3.1416" xyz="0 0 0"/>
      <mass value="2.8"/>
      <inertia ixx="0.00396666666667" ixy="0.0" ixz="0.0" iyy="0.00571666666667" iyz="0.0" izz="0.00739666666667"/>
    </inertial>
  </link>
  <joint name="base_inertia_joint" type="fixed">
    <parent link="base_link"/>
    <child link="base_inertia"/>
  </joint>
  <link name="rear_link">
    <visual>
      <geometry>
        <mesh filename="package://spotmicro_description/meshes/stl/backpart.stl" scale="0.001 0.001 0.001"/>
      </geometry>
      <origin rpy="0 0 3.1416" xyz="0.042 0.055 -0.0195"/>
      <material name="yellow"/>
    </visual>
    <collision>
      <geometry>
        <box size="0.04 0.11 0.07"/>
      </geometry>
      <origin rpy="0 0 0" xyz="-0.135 0 0"/>
    </collision>
    <inertial>
      <origin rpy="0 0 0" xyz="-0.135 0 0"/>
      <mass value="0.2"/>
      <inertia ixx="0.000283333333333" ixy="0.0" ixz="0.0" iyy="0.000108333333333" iyz="0.0" izz="0.000228333333333"/>
    </inertial>
  </link>
  <joint name="base_rear" type="fixed">
    <parent link="base_link"/>
    <child link="rear_link"/>
  </joint>
  <gazebo reference="rear_link">
    <material>Gazebo/ZincYellow</material>
  </gazebo>
  <link name="front_link">
    <visual>
      <geometry>
        <mesh filename="package://spotmicro_description/meshes/stl/frontpart.stl" scale="0.001 0.001 0.001"/>
      </geometry>
      <origin rpy="0 0 3.1416" xyz="0.042 0.055 -0.0205"/>
      <material name="yellow"/>
    </visual>
    <collision>
      <geometry>
        <box size="0.058 0.11 0.07"/>
      </geometry>
      <origin rpy="0 0 0" xyz="0.135 0 0"/>
    </collision>
    <inertial>
      <origin rpy="0 0 0" xyz="0.135 0 0"/>
      <mass value="0.2"/>
      <inertia ixx="0.000283333333333" ixy="0.0" ixz="0.0" iyy="0.000137733333333" iyz="0.0" izz="0.000257733333333"/>
    </inertial>
  </link>
  <gazebo reference="front_link">
    <material>Gazebo/ZincYellow</material>
  </gazebo>
  <joint name="base_front" type="fixed">
    <parent link="base_link"/>
    <child link="front_link"/>
  </joint>
  <link name="front_left_shoulder_link">
    <visual>
      <geometry>
        <mesh filename="package://spotmicro_description/meshes/stl/lshoulder.stl" scale="0.001 0.001 0.001"/>
      </geometry>
      <origin rpy="0 0 3.1416" xyz="0.135 0.0163 -0.0195"/>
      <material name="black"/>
    </visual>
    <collision>
      <geometry>
        <box size="0.044 0.038 0.07"/>
      </geometry>
      <origin rpy="0 0 0" xyz="0 0 0"/>
    </collision>
    <inertial>
      <mass value="0.1"/>
      <origin xyz="0 0 0"/>
      <inertia ixx="5.28666666667e-05" ixy="0.0" ixz="0.0" iyy="5.69666666667e-05" iyz="0.0" izz="2.81666666667e-05"/>
    </inertial>
  </link>
  <link name="front_left_leg_link_cover">
    <visual>
      <geometry>
        <mesh filename="package://spotmicro_description/meshes/stl/larm_cover.stl" scale="0.001 0.001 0.001"/>
      </geometry>
      <origin rpy="0 0 3.1416" xyz="0.134 -0.04 -0.0095"/>
      <material name="yellow"/>
    </visual>
  </link>
  <link name="front_left_leg_link">
    <visual>
      <geometry>
        <mesh filename="package://spotmicro_description/meshes/stl/larm.stl" scale="0.001 0.001 0.001"/>
      </geometry>
      <origin rpy="0 0 3.1416" xyz="0.134 -0.04 -0.0095"/>
      <material name="black"/>
    </visual>
    <collision>
      <origin rpy="0 0 0" xyz="0 0 -0.050"/>
      <geometry>
        <box size="0.028 0.036 0.109"/>
      </geometry>
    </collision>
    <inertial>
      <origin rpy="0 0 0" xyz="0 0 -0.050"/>
      <mass value="0.15"/>
      <inertia ixx="0.0001647125" ixy="0.0" ixz="0.0" iyy="0.0001583125" iyz="0.0" izz="2.6e-05"/>
    </inertial>
  </link>
  <gazebo reference="front_left_leg_link_cover">
    <material>Gazebo/ZincYellow</material>
  </gazebo>
  <link name="front_left_foot_link">
    <visual>
      <geometry>
        <mesh filename="package://spotmicro_description/meshes/stl/lfoot.stl" scale="0.001 0.001 0.001"/>
      </geometry>
      <origin rpy="0 0 3.1416 " xyz="0.1195 -0.04 0.099"/>
      <material name="black"/>
    </visual>
    <collision>
      <geometry>
        <box size="0.026 0.02 0.125"/>
      </geometry>
      <origin rpy="0 0 0" xyz="0 0 -0.050"/>
    </collision>
    <inertial>
      <origin rpy="0 0 0" xyz="0 0 -0.050"/>
      <mass value="0.1"/>
      <inertia ixx="0.000133541666667" ixy="0.0" ixz="0.0" iyy="0.000135841666667" iyz="0.0" izz="8.96666666667e-06"/>
    </inertial>
  </link>
  <gazebo reference="front_left_foot_link">
    <kp>100000.0</kp>
    <kd>1.0</kd>
    <mu1>0.8</mu1>
    <mu2>0.8</mu2>
    <maxVel>0.0</maxVel>
    <minDepth>0.001</minDepth>
  </gazebo>
  <link name="front_left_toe_link">
    <visual>
      <geometry>
        <mesh filename="package://spotmicro_description/meshes/stl/foot.stl" scale="0.001 0.001 0.001"/>
      </geometry>
      <origin rpy="0 0.40010 0" xyz="0 -0.01 0.005"/>
      <material name="grey"/>
    </visual>
    <collision>
      <geometry>
        <sphere radius="0.015"/>
      </geometry>
      <origin rpy="0 0 0" xyz="0 0 0"/>
      <contact_coefficients mu="1.1"/>
    </collision>
    <inertial>
      <mass value="0.05"/>
      <origin xyz="0 0 0"/>
      <inertia ixx="1.125e-06" ixy="0.0" ixz="0.0" iyy="1.125e-06" iyz="0.0" izz="1.125e-06"/>
    </inertial>
  </link>
  <gazebo reference="front_left_toe_link">
    <kp>100000.0</kp>
    <kd>1.0</kd>
    <mu1>1.0</mu1>
    <mu2>1.0</mu2>
    <maxVel>0.0</maxVel>
    <minDepth>0.001</minDepth>
  </gazebo>
  <joint name="front_left_shoulder" type="revolute">
    <parent link="base_link"/>
    <child link="front_left_shoulder_link"/>
    <axis xyz="1 0 0"/>
    <origin rpy="0 0 0" xyz="0.093 0.0395 0"/>
    <limit effort="100.0" lower="-0.548" upper="0.548" velocity="0.7"/>
  </joint>
  <transmission name="front_left_shoulder_trans">
    <type>transmission_interface/SimpleTransmission</type>
    <joint name="front_left_shoulder">
      <hardwareInterface>hardware_interface/EffortJointInterface</hardwareInterface>
    </joint>
    <actuator name="front_left_shoulder_actuator">
      <hardwareInterface>hardware_interface/EffortJointInterface</hardwareInterface>
      <mechanicalReduction>1</mechanicalReduction>
    </actuator>
  </transmission>
  <joint name="front_left_leg" type="revolute">
    <parent link="front_left_shoulder_link"/>
    <child link="front_left_leg_link"/>
    <axis xyz="0 1 0"/>
    <origin rpy="0 0 0" xyz="0 0.055 0"/>
    <limit effort="100.0" lower="-2.666" upper="1.548" velocity="0.5"/>
  </joint>
  <transmission name="front_left_leg_trans">
    <type>transmission_interface/SimpleTransmission</type>
    <joint name="front_left_leg">
      <hardwareInterface>hardware_interface/EffortJointInterface</hardwareInterface>
    </joint>
    <actuator name="front_left_leg_actuator">
      <hardwareInterface>hardware_interface/EffortJointInterface</hardwareInterface>
      <mechanicalReduction>1</mechanicalReduction>
    </actuator>
  </transmission>
  <joint name="front_left_leg_cover_joint" type="fixed">
    <parent link="front_left_leg_link"/>
    <child link="front_left_leg_link_cover"/>
    <origin xyz="0 0 0"/>
  </joint>
  <joint name="front_left_foot" type="revolute">
    <parent link="front_left_leg_link"/>
    <child link="front_left_foot_link"/>
    <axis xyz="0 1 0"/>
    <origin rpy="0 0 0" xyz="0.014 0 -0.109"/>
    <limit effort="100.0" lower="-1.7929" upper="0.254801" velocity="0.5"/>
  </joint>
  <transmission name="front_left_foot_trans">
    <type>transmission_interface/SimpleTransmission</type>
    <joint name="front_left_foot">
      <hardwareInterface>hardware_interface/EffortJointInterface</hardwareInterface>
    </joint>
    <actuator name="front_left_foot_actuator">
      <hardwareInterface>hardware_interface/EffortJointInterface</hardwareInterface>
      <mechanicalReduction>1</mechanicalReduction>
    </actuator>
  </transmission>
  <joint name="front_left_toe" type="fixed">
    <parent link="front_left_foot_link"/>
    <child link="front_left_toe_link"/>
    <origin xyz="0 0 -0.125"/>
  </joint>
  <link name="front_right_shoulder_link">
    <visual>
      <geometry>
        <mesh filename="package://spotmicro_description/meshes/stl/rshoulder.stl" scale="0.001 0.001 0.001"/>
      </geometry>
      <origin rpy="0 0 3.1416" xyz="0.135 0.0938 -0.0205"/>
      <material name="black"/>
    </visual>
    <collision>
      <geometry>
        <box size="0.044 0.038 0.07"/>
      </geometry>
      <origin rpy="0 0 0" xyz="0 0 0"/>
    </collision>
    <inertial>
      <mass value="0.1"/>
      <origin xyz="0 0 0"/>
      <inertia ixx="5.28666666667e-05" ixy="0.0" ixz="0.0" iyy="5.69666666667e-05" iyz="0.0" izz="2.81666666667e-05"/>
    </inertial>
  </link>
  <link name="front_right_leg_link_cover">
    <visual>
      <geometry>
        <mesh filename="package://spotmicro_description/meshes/stl/rarm_cover.stl" scale="0.001 0.001 0.001"/>
      </geometry>
      <origin rpy="0 0 3.1416" xyz="0.134 0.149 -0.0095"/>
      <material name="yellow"/>
    </visual>
  </link>
  <link name="front_right_leg_link">
    <visual>
      <geometry>
        <mesh filename="package://spotmicro_description/meshes/stl/rarm.stl" scale="0.001 0.001 0.001"/>
      </geometry>
      <origin rpy="0 0 3.1416" xyz="0.134 0.149 -0.0095"/>
      <material name="black"/>
    </visual>
    <collision>
      <origin rpy="0 0 0" xyz="0 0 -0.050"/>
      <geometry>
        <box size="0.028 0.036 0.109"/>
      </geometry>
    </collision>
    <inertial>
      <origin rpy="0 0 0" xyz="0 0 -0.050"/>
      <mass value="0.15"/>
      <inertia ixx="0.0001647125" ixy="0.0" ixz="0.0" iyy="0.0001583125" iyz="0.0" izz="2.6e-05"/>
    </inertial>
  </link>
  <gazebo reference="front_right_leg_link_cover">
    <material>Gazebo/ZincYellow</material>
  </gazebo>
  <link name="front_right_foot_link">
    <visual>
      <geometry>
        <mesh filename="package://spotmicro_description/meshes/stl/rfoot.stl" scale="0.001 0.001 0.001"/>
      </geometry>
      <origin rpy="0 0 3.1416" xyz="0.1195 0.149 0.099"/>
      <material name="black"/>
    </visual>
    <collision>
      <geometry>
        <box size="0.026 0.02 0.125"/>
      </geometry>
      <origin rpy="0 0 0" xyz="0 0 -0.050"/>
    </collision>
    <inertial>
      <origin rpy="0 0 0" xyz="0 0 -0.050"/>
      <mass value="0.1"/>
      <inertia ixx="0.000133541666667" ixy="0.0" ixz="0.0" iyy="0.000135841666667" iyz="0.0" izz="8.96666666667e-06"/>
    </inertial>
  </link>
  <gazebo reference="front_right_foot_link">
    <kp>100000.0</kp>
    <kd>1.0</kd>
    <mu1>0.8</mu1>
    <mu2>0.8</mu2>
    <maxVel>0.0</maxVel>
    <minDepth>0.001</minDepth>
  </gazebo>
  <link name="front_right_toe_link">
    <visual>
      <geometry>
        <mesh filename="package://spotmicro_description/meshes/stl/foot.stl" scale="0.001 0.001 0.001"/>
      </geometry>
      <origin rpy="0 0.40010 0" xyz="0 -0.01 0.005"/>
      <material name="grey"/>
    </visual>
    <collision>
      <geometry>
        <sphere radius="0.015"/>
      </geometry>
      <origin rpy="0 0 0" xyz="0 0 0"/>
      <contact_coefficients mu="1.1"/>
    </collision>
    <inertial>
      <mass value="0.05"/>
      <origin xyz="0 0 0"/>
      <inertia ixx="1.125e-06" ixy="0.0" ixz="0.0" iyy="1.125e-06" iyz="0.0" izz="1.125e-06"/>
    </inertial>
  </link>
  <gazebo reference="front_right_toe_link">
    <kp>100000.0</kp>
    <kd>1.0</kd>
    <mu1>1.0</mu1>
    <mu2>1.0</mu2>
    <maxVel>0.0</maxVel>
    <minDepth>0.001</minDepth>
  </gazebo>
  <joint name="front_right_shoulder" type="revolute">
    <parent link="base_link"/>
    <child link="front_right_shoulder_link"/>
    <axis xyz="1 0 0"/>
    <origin rpy="0 0 0" xyz="0.093 -0.0395 0"/>
    <limit effort="100.0" lower="-0.548" upper="0.548" velocity="0.7"/>
  </joint>
  <transmission name="front_right_shoulder_trans">
    <type>transmission_interface/SimpleTransmission</type>
    <joint name="front_right_shoulder">
      <hardwareInterface>hardware_interface/EffortJointInterface</hardwareInterface>
    </joint>
    <actuator name="front_right_shoulder_actuator">
      <hardwareInterface>hardware_interface/EffortJointInterface</hardwareInterface>
      <mechanicalReduction>1</mechanicalReduction>
    </actuator>
  </transmission>
  <joint name="front_right_leg" type="revolute">
    <parent link="front_right_shoulder_link"/>
    <child link="front_right_leg_link"/>
    <axis xyz="0 1 0"/>
    <origin rpy="0 0 0" xyz="0 -0.055 0"/>
    <limit effort="100.0" lower="-2.666" upper="1.548" velocity="0.5"/>
  </joint>
  <transmission name="front_right_leg_trans">
    <type>transmission_interface/SimpleTransmission</type>
    <joint name="front_right_leg">
      <hardwareInterface>hardware_interface/EffortJointInterface</hardwareInterface>
    </joint>
    <actuator name="front_right_leg_actuator">
      <hardwareInterface>hardware_interface/EffortJointInterface</hardwareInterface>
      <mechanicalReduction>1</mechanicalReduction>
    </actuator>
  </transmission>
  <joint name="front_right_leg_cover_joint" type="fixed">
    <parent link="front_right_leg_link"/>
    <child link="front_right_leg_link_cover"/>
    <origin xyz="0 0 0"/>
  </joint>
  <joint name="front_right_foot" type="revolute">
    <parent link="front_right_leg_link"/>
    <child link="front_right_foot_link"/>
    <axis xyz="0 1 0"/>
    <origin rpy="0 0 0" xyz="0.014 0 -0.109"/>
    <limit effort="100.0" lower="-1.7929" upper="0.254801" velocity="0.5"/>
  </joint>
  <transmission name="front_right_foot_trans">
    <type>transmission_interface/SimpleTransmission</type>
    <joint name="front_right_foot">
      <hardwareInterface>hardware_interface/EffortJointInterface</hardwareInterface>
    </joint>
    <actuator name="front_right_foot_actuator">
      <hardwareInterface>hardware_interface/EffortJointInterface</hardwareInterface>
      <mechanicalReduction>1</mechanicalReduction>
    </actuator>
  </transmission>
  <joint name="front_right_toe" type="fixed">
    <parent link="front_right_foot_link"/>
    <child link="front_right_toe_link"/>
    <origin xyz="0 0 -0.125"/>
  </joint>
  <link name="rear_left_shoulder_link">
    <visual>
      <geometry>
        <mesh filename="package://spotmicro_description/meshes/stl/lshoulder.stl" scale="0.001 0.001 0.001"/>
      </geometry>
      <origin rpy="0 0 3.1416" xyz="0.135 0.0163 -0.0195"/>
      <material name="black"/>
    </visual>
    <collision>
      <geometry>
        <box size="0.044 0.038 0.07"/>
      </geometry>
      <origin rpy="0 0 0" xyz="0 0 0"/>
    </collision>
    <inertial>
      <mass value="0.1"/>
      <origin xyz="0 0 0"/>
      <inertia ixx="5.28666666667e-05" ixy="0.0" ixz="0.0" iyy="5.69666666667e-05" iyz="0.0" izz="2.81666666667e-05"/>
    </inertial>
  </link>
  <link name="rear_left_leg_link_cover">
    <visual>
      <geometry>
        <mesh filename="package://spotmicro_description/meshes/stl/larm_cover.stl" scale="0.001 0.001 0.001"/>
      </geometry>
      <origin rpy="0 0 3.1416" xyz="0.134 -0.04 -0.0095"/>
      <material name="yellow"/>
    </visual>
  </link>
  <link name="rear_left_leg_link">
    <visual>
      <geometry>
        <mesh filename="package://spotmicro_description/meshes/stl/larm.stl" scale="0.001 0.001 0.001"/>
      </geometry>
      <origin rpy="0 0 3.1416" xyz="0.134 -0.04 -0.0095"/>
      <material name="black"/>
    </visual>
    <collision>
      <origin rpy="0 0 0" xyz="0 0 -0.050"/>
      <geometry>
        <box size="0.028 0.036 0.109"/>
      </geometry>
    </collision>
    <inertial>
      <origin rpy="0 0 0" xyz="0 0 -0.050"/>
      <mass value="0.15"/>
      <inertia ixx="0.0001647125" ixy="0.0" ixz="0.0" iyy="0.0001583125" iyz="0.0" izz="2.6e-05"/>
    </inertial>
  </link>
  <gazebo reference="rear_left_leg_link_cover">
    <material>Gazebo/ZincYellow</material>
  </gazebo>
  <link name="rear_left_foot_link">
    <visual>
      <geometry>
        <mesh filename="package://spotmicro_description/meshes/stl/lfoot.stl" scale="0.001 0.001 0.001"/>
      </geometry>
      <origin rpy="0 0 3.1416 " xyz="0.1195 -0.04 0.099"/>
      <material name="black"/>
    </visual>
    <collision>
      <geometry>
        <box size="0.026 0.02 0.125"/>
      </geometry>
      <origin rpy="0 0 0" xyz="0 0 -0.050"/>
    </collision>
    <inertial>
      <origin rpy="0 0 0" xyz="0 0 -0.050"/>
      <mass value="0.1"/>
      <inertia ixx="0.000133541666667" ixy="0.0" ixz="0.0" iyy="0.000135841666667" iyz="0.0" izz="8.96666666667e-06"/>
    </inertial>
  </link>
  <gazebo reference="rear_left_foot_link">
    <kp>100000.0</kp>
    <kd>1.0</kd>
    <mu1>0.8</mu1>
    <mu2>0.8</mu2>
    <maxVel>0.0</maxVel>
    <minDepth>0.001</minDepth>
  </gazebo>
  <link name="rear_left_toe_link">
    <visual>
      <geometry>
        <mesh filename="package://spotmicro_description/meshes/stl/foot.stl" scale="0.001 0.001 0.001"/>
      </geometry>
      <origin rpy="0 0.40010 0" xyz="0 -0.01 0.005"/>
      <material name="grey"/>
    </visual>
    <collision>
      <geometry>
        <sphere radius="0.015"/>
      </geometry>
      <origin rpy="0 0 0" xyz="0 0 0"/>
      <contact_coefficients mu="1.1"/>
    </collision>
    <inertial>
      <mass value="0.05"/>
      <origin xyz="0 0 0"/>
      <inertia ixx="1.125e-06" ixy="0.0" ixz="0.0" iyy="1.125e-06" iyz="0.0" izz="1.125e-06"/>
    </inertial>
  </link>
  <gazebo reference="rear_left_toe_link">
    <kp>100000.0</kp>
    <kd>1.0</kd>
    <mu1>1.0</mu1>
    <mu2>1.0</mu2>
    <maxVel>0.0</maxVel>
    <minDepth>0.001</minDepth>
  </gazebo>
  <joint name="rear_left_shoulder" type="revolute">
    <parent link="base_link"/>
    <child link="rear_left_shoulder_link"/>
    <axis xyz="1 0 0"/>
    <origin rpy="0 0 0" xyz="-0.093 0.0395 0"/>
    <limit effort="100.0" lower="-0.548" upper="0.548" velocity="0.7"/>
  </joint>
  <transmission name="rear_left_shoulder_trans">
    <type>transmission_interface/SimpleTransmission</type>
    <joint name="rear_left_shoulder">
      <hardwareInterface>hardware_interface/EffortJointInterface</hardwareInterface>
    </joint>
    <actuator name="rear_left_shoulder_actuator">
      <hardwareInterface>hardware_interface/EffortJointInterface</hardwareInterface>
      <mechanicalReduction>1</mechanicalReduction>
    </actuator>
  </transmission>
  <joint name="rear_left_leg" type="revolute">
    <parent link="rear_left_shoulder_link"/>
    <child link="rear_left_leg_link"/>
    <axis xyz="0 1 0"/>
    <origin rpy="0 0 0" xyz="0 0.055 0"/>
    <limit effort="100.0" lower="-2.666" upper="1.548" velocity="0.5"/>
  </joint>
  <transmission name="rear_left_leg_trans">
    <type>transmission_interface/SimpleTransmission</type>
    <joint name="rear_left_leg">
      <hardwareInterface>hardware_interface/EffortJointInterface</hardwareInterface>
    </joint>
    <actuator name="rear_left_leg_actuator">
      <hardwareInterface>hardware_interface/EffortJointInterface</hardwareInterface>
      <mechanicalReduction>1</mechanicalReduction>
    </actuator>
  </transmission>
  <joint name="rear_left_leg_cover_joint" type="fixed">
    <parent link="rear_left_leg_link"/>
    <child link="rear_left_leg_link_cover"/>
    <origin xyz="0 0 0"/>
  </joint>
  <joint name="rear_left_foot" type="revolute">
    <parent link="rear_left_leg_link"/>
    <child link="rear_left_foot_link"/>
    <axis xyz="0 1 0"/>
    <origin rpy="0 0 0" xyz="0.014 0 -0.109"/>
    <limit effort="100.0" lower="-1.7929" upper="0.254801" velocity="0.5"/>
  </joint>
  <transmission name="rear_left_foot_trans">
    <type>transmission_interface/SimpleTransmission</type>
    <joint name="rear_left_foot">
      <hardwareInterface>hardware_interface/EffortJointInterface</hardwareInterface>
    </joint>
    <actuator name="rear_left_foot_actuator">
      <hardwareInterface>hardware_interface/EffortJointInterface</hardwareInterface>
      <mechanicalReduction>1</mechanicalReduction>
    </actuator>
  </transmission>
  <joint name="rear_left_toe" type="fixed">
    <parent link="rear_left_foot_link"/>
    <child link="rear_left_toe_link"/>
    <origin xyz="0 0 -0.125"/>
  </joint>
  <link name="rear_right_shoulder_link">
    <visual>
      <geometry>
        <mesh filename="package://spotmicro_description/meshes/stl/rshoulder.stl" scale="0.001 0.001 0.001"/>
      </geometry>
      <origin rpy="0 0 3.1416" xyz="0.135 0.0938 -0.0205"/>
      <material name="black"/>
    </visual>
    <collision>
      <geometry>
        <box size="0.044 0.038 0.07"/>
      </geometry>
      <origin rpy="0 0 0" xyz="0 0 0"/>
    </collision>
    <inertial>
      <mass value="0.1"/>
      <origin xyz="0 0 0"/>
      <inertia ixx="5.28666666667e-05" ixy="0.0" ixz="0.0" iyy="5.69666666667e-05" iyz="0.0" izz="2.81666666667e-05"/>
    </inertial>
  </link>
  <link name="rear_right_leg_link_cover">
    <visual>
      <geometry>
        <mesh filename="package://spotmicro_description/meshes/stl/rarm_cover.stl" scale="0.001 0.001 0.001"/>
      </geometry>
      <origin rpy="0 0 3.1416" xyz="0.134 0.149 -0.0095"/>
      <material name="yellow"/>
    </visual>
  </link>
  <link name="rear_right_leg_link">
    <visual>
      <geometry>
        <mesh filename="package://spotmicro_description/meshes/stl/rarm.stl" scale="0.001 0.001 0.001"/>
      </geometry>
      <origin rpy="0 0 3.1416" xyz="0.134 0.149 -0.0095"/>
      <material name="black"/>
    </visual>
    <collision>
      <origin rpy="0 0 0" xyz="0 0 -0.050"/>
      <geometry>
        <box size="0.028 0.036 0.109"/>
      </geometry>
    </collision>
    <inertial>
      <origin rpy="0 0 0" xyz="0 0 -0.050"/>
      <mass value="0.15"/>
      <inertia ixx="0.0001647125" ixy="0.0" ixz="0.0" iyy="0.0001583125" iyz="0.0" izz="2.6e-05"/>
    </inertial>
  </link>
  <gazebo reference="rear_right_leg_link_cover">
    <material>Gazebo/ZincYellow</material>
  </gazebo>
  <link name="rear_right_foot_link">
    <visual>
      <geometry>
        <mesh filename="package://spotmicro_description/meshes/stl/rfoot.stl" scale="0.001 0.001 0.001"/>
      </geometry>
      <origin rpy="0 0 3.1416" xyz="0.1195 0.149 0.099"/>
      <material name="black"/>
    </visual>
    <collision>
      <geometry>
        <box size="0.026 0.02 0.125"/>
      </geometry>
      <origin rpy="0 0 0" xyz="0 0 -0.050"/>
    </collision>
    <inertial>
      <origin rpy="0 0 0" xyz="0 0 -0.050"/>
      <mass value="0.1"/>
      <inertia ixx="0.000133541666667" ixy="0.0" ixz="0.0" iyy="0.000135841666667" iyz="0.0" izz="8.96666666667e-06"/>
    </inertial>
  </link>
  <gazebo reference="rear_right_foot_link">
    <kp>100000.0</kp>
    <kd>1.0</kd>
    <mu1>0.8</mu1>
    <mu2>0.8</mu2>
    <maxVel>0.0</maxVel>
    <minDepth>0.001</minDepth>
  </gazebo>
  <link name="rear_right_toe_link">
    <visual>
      <geometry>
        <mesh filename="package://spotmicro_description/meshes/stl/foot.stl" scale="0.001 0.001 0.001"/>
      </geometry>
      <origin rpy="0 0.40010 0" xyz="0 -0.01 0.005"/>
      <material name="grey"/>
    </visual>
    <collision>
      <geometry>
        <sphere radius="0.015"/>
      </geometry>
      <origin rpy="0 0 0" xyz="0 0 0"/>
      <contact_coefficients mu="1.1"/>
    </collision>
    <inertial>
      <mass value="0.05"/>
      <origin xyz="0 0 0"/>
      <inertia ixx="1.125e-06" ixy="0.0" ixz="0.0" iyy="1.125e-06" iyz="0.0" izz="1.125e-06"/>
    </inertial>
  </link>
  <gazebo reference="rear_right_toe_link">
    <kp>100000.0</kp>
    <kd>1.0</kd>
    <mu1>1.0</mu1>
    <mu2>1.0</mu2>
    <maxVel>0.0</maxVel>
    <minDepth>0.001</minDepth>
  </gazebo>
  <joint name="rear_right_shoulder" type="revolute">
    <parent link="base_link"/>
    <child link="rear_right_shoulder_link"/>
    <axis xyz="1 0 0"/>
    <origin rpy="0 0 0" xyz="-0.093 -0.0395 0"/>
    <limit effort="100.0" lower="-0.548" upper="0.548" velocity="0.7"/>
  </joint>
  <transmission name="rear_right_shoulder_trans">
    <type>transmission_interface/SimpleTransmission</type>
    <joint name="rear_right_shoulder">
      <hardwareInterface>hardware_interface/EffortJointInterface</hardwareInterface>
    </joint>
    <actuator name="rear_right_shoulder_actuator">
      <hardwareInterface>hardware_interface/EffortJointInterface</hardwareInterface>
      <mechanicalReduction>1</mechanicalReduction>
    </actuator>
  </transmission>
  <joint name="rear_right_leg" type="revolute">
    <parent link="rear_right_shoulder_link"/>
    <child link="rear_right_leg_link"/>
    <axis xyz="0 1 0"/>
    <origin rpy="0 0 0" xyz="0 -0.055 0"/>
    <limit effort="100.0" lower="-2.666" upper="1.548" velocity="0.5"/>
  </joint>
  <transmission name="rear_right_leg_trans">
    <type>transmission_interface/SimpleTransmission</type>
    <joint name="rear_right_leg">
      <hardwareInterface>hardware_interface/EffortJointInterface</hardwareInterface>
    </joint>
    <actuator name="rear_right_leg_actuator">
      <hardwareInterface>hardware_interface/EffortJointInterface</hardwareInterface>
      <mechanicalReduction>1</mechanicalReduction>
    </actuator>
  </transmission>
  <joint name="rear_right_leg_cover_joint" type="fixed">
    <parent link="rear_right_leg_link"/>
    <child link="rear_right_leg_link_cover"/>
    <origin xyz="0 0 0"/>
  </joint>
  <joint name="rear_right_foot" type="revolute">
    <parent link="rear_right_leg_link"/>
    <child link="rear_right_foot_link"/>
    <axis xyz="0 1 0"/>
    <origin rpy="0 0 0" xyz="0.014 0 -0.109"/>
    <limit effort="100.0" lower="-1.7929" upper="0.254801" velocity="0.5"/>
  </joint>
  <transmission name="rear_right_foot_trans">
    <type>transmission_interface/SimpleTransmission</type>
    <joint name="rear_right_foot">
      <hardwareInterface>hardware_interface/EffortJointInterface</hardwareInterface>
    </joint>
    <actuator name="rear_right_foot_actuator">
      <hardwareInterface>hardware_interface/EffortJointInterface</hardwareInterface>
      <mechanicalReduction>1</mechanicalReduction>
    </actuator>
  </transmission>
  <joint name="rear_right_toe" type="fixed">
    <parent link="rear_right_foot_link"/>
    <child link="rear_right_toe_link"/>
    <origin xyz="0 0 -0.125"/>
  </joint>
  <!-- This file is a placeholder which is included by default from
       spotmicroai.urdf.xacro. If a robot is being customized and requires
       additional URDF, set the SPOT_URDF_EXTRAS environment variable
       to the full path of the file you would like included. -->
  <!-- <xacro:hokuyo_utm30lx
        name="hokuyo"
        parent="base_link"
        ros_topic="scan"
        update_rate="30"
        ray_count="1040"
        min_angle="130"
        max_angle="-130" >
        <origin xyz="0.0 0.0 ${body_height / 2 + 0.04}" rpy="0 0 0"/>
    </xacro:hokuyo_utm30lx> -->
  <gazebo reference="hokuyo_frame">
    <material>Gazebo/FlatBlack</material>
  </gazebo>
  <!-- <xacro:asus_camera
        parent="base_link"
        name="camera">
        <origin xyz="${body_length / 2 - 0.05} 0.0 -${body_height / 2 + 0.01}" rpy="0 0 0"/>
    </xacro:asus_camera> -->
  <gazebo>
    <plugin filename="libhector_gazebo_ros_imu.so" name="imu_controller">
      <updateRate>50.0</updateRate>
      <bodyName>imu_link</bodyName>
      <topicName>imu/data</topicName>
      <accelDrift>0.005 0.005 0.005</accelDrift>
      <accelGaussianNoise>0.005 0.005 0.005</accelGaussianNoise>
      <rateDrift>0.005 0.005 0.005 </rateDrift>
      <rateGaussianNoise>0.005 0.005 0.005 </rateGaussianNoise>
      <headingDrift>0.005</headingDrift>
      <headingGaussianNoise>0.005</headingGaussianNoise>
    </plugin>
  </gazebo>
  <link name="imu_link">
    <inertial>
      <mass value="0.001"/>
      <origin rpy="0 0 0" xyz="0 0 0"/>
      <inertia ixx="1e-09" ixy="0.0" ixz="0.0" iyy="1e-09" iyz="0.0" izz="1e-09"/>
    </inertial>
  </link>
  <joint name="imu_joint" type="fixed">
    <parent link="base_link"/>
    <child link="imu_link"/>
  </joint>
  <!-- <xacro:include filename="$(find velodyne_description)/urdf/VLP-16.urdf.xacro"/>
    <xacro:VLP-16 parent="base_link" name="velodyne" topic="velodyne_points" hz="10" samples="1024" gpu="false" lasers="16" max_range="100">
        <origin xyz="0.29 0 ${(body_height / 2) - 0.01}" rpy="0 0 0" />
    </xacro:VLP-16> -->
  <!-- Gazebo plugins -->
  <gazebo>
    <plugin filename="libgazebo_ros_p3d.so" name="p3d_base_controller">
      <alwaysOn>true</alwaysOn>
      <updateRate>10.0</updateRate>
      <bodyName>base_link</bodyName>
      <topicName>odom/ground_truth</topicName>
      <gaussianNoise>0.01</gaussianNoise>
      <frameName>world</frameName>
      <xyzOffsets>0 0 0</xyzOffsets>
      <rpyOffsets>0 0 0</rpyOffsets>
    </plugin>
  </gazebo>
  <gazebo>
    <plugin filename="libgazebo_ros_control.so" name="gazebo_ros_control">
      <legacyModeNS>true</legacyModeNS>
    </plugin>
  </gazebo>
</robot>

