<?xml version="1.0" encoding="utf-8"?>
<!-- =================================================================================== -->
<!-- |    This document was autogenerated by xacro from spotmicroai.urdf.xacro         | -->
<!-- |    EDITING THIS FILE BY HAND IS NOT RECOMMENDED                                 | -->
<!-- =================================================================================== -->
<robot name="SpotMicroAI">
  <!-- Materials -->
  <material name="yellow">
    <color rgba="0.92 0.83 0.0 1"/>
  </material>
  <material name="black">
    <color rgba="0.1 0.1 0.1 1"/>
  </material>
  <material name="grey">
    <color rgba="0.6 0.6 0.6 1"/>
  </material>
  <!-- Robot Body -->
  <link name="base_link"/>
  <link name="base_inertia">
    <visual>
      <geometry>
        <mesh filename="package://spotmicro_description/meshes/stl/mainbody.stl" scale="0.001 0.001 0.001"/>
      </geometry>
      <material name="black"/>
      <origin rpy="0 0 3.1416" xyz="0.0425 0.055 -0.02"/>
    </visual>
    <collision>
      <geometry>
        <box size="0.14 0.11 0.07"/>
      </geometry>
      <origin rpy="0 0 3.1416"/>
    </collision>
    <inertial>
      <mass value="2.8"/>
      <origin xyz="0 0 0"/>
      <inertia ixx="0.00396666666667" ixy="0.0" ixz="0.0" iyy="0.00571666666667" iyz="0.0" izz="0.00739666666667"/>
    </inertial>
  </link>
  <gazebo reference="base_inertia">
    <mu1>100000.0</mu1>
    <mu2>100000.0</mu2>
  </gazebo>
  <joint name="base_link_to_base_inertia" type="fixed">
    <parent link="base_link"/>
    <child link="base_inertia"/>
  </joint>
  <gazebo reference="base_link_to_base_inertia">
    <provideFeedback>true</provideFeedback>
    <disableFixedJointLumping>true</disableFixedJointLumping>
  </gazebo>
  <link name="rear_link">
    <visual>
      <geometry>
        <mesh filename="package://spotmicro_description/meshes/stl/Cover_Rear_Plain.stl" scale="0.001 0.001 0.001"/>
      </geometry>
      <origin rpy="0 1.57 0" xyz="-0.115 0 -0.006"/>
      <material name="yellow"/>
    </visual>
    <visual>
      <geometry>
        <mesh filename="package://spotmicro_description/meshes/stl/B_cover.stl" scale="0.001 0.001 0.001"/>
      </geometry>
      <origin rpy="1.57 0 3.1416" xyz="0 0 -0.04"/>
      <material name="yellow"/>
    </visual>
    <collision>
      <geometry>
        <box size="0.04 0.11 0.07"/>
      </geometry>
      <origin xyz="-0.135 0 0"/>
    </collision>
    <inertial>
      <origin xyz="-0.135 0 0"/>
      <mass value="0.3"/>
      <inertia ixx="0.000425" ixy="0.0" ixz="0.0" iyy="0.0001625" iyz="0.0" izz="0.0003425"/>
    </inertial>
  </link>
  <joint name="base_rear" type="fixed">
    <parent link="base_link"/>
    <child link="rear_link"/>
  </joint>
  <gazebo reference="rear_link">
    <material>Gazebo/ZincYellow</material>
  </gazebo>
  <link name="front_link">
    <visual>
      <geometry>
        <mesh filename="package://spotmicro_description/meshes/stl/Cover_Nose_Realsense.STL" scale="0.001 0.001 0.001"/>
      </geometry>
      <origin rpy="3.1416 0 0" xyz="0.13 -0.001 -0.01"/>
      <material name="yellow"/>
    </visual>
    <collision>
      <geometry>
        <box size="0.058 0.11 0.07"/>
      </geometry>
      <origin xyz="0.135 0 0"/>
    </collision>
    <inertial>
      <origin xyz="0.135 0 0"/>
      <mass value="0.3"/>
      <inertia ixx="0.000425" ixy="0.0" ixz="0.0" iyy="0.0002066" iyz="0.0" izz="0.0003866"/>
    </inertial>
  </link>
  <gazebo reference="front_link">
    <material>Gazebo/ZincYellow</material>
  </gazebo>
  <joint name="base_front" type="fixed">
    <parent link="base_link"/>
    <child link="front_link"/>
  </joint>
  <link name="front_left_shoulder_link">
    <visual>
      <geometry>
        <mesh filename="package://spotmicro_description/meshes/stl/lshoulder.stl" scale="0.001 0.001 0.001"/>
      </geometry>
      <origin rpy="0 0 3.1416" xyz="0.135 0.0163 -0.0195"/>
      <material name="black"/>
    </visual>
    <collision>
      <geometry>
        <box size="0.044 0.038 0.07"/>
      </geometry>
    </collision>
    <inertial>
      <mass value="0.3"/>
      <origin xyz="0 0 0"/>
      <inertia ixx="0.0001586" ixy="0.0" ixz="0.0" iyy="0.0001709" iyz="0.0" izz="8.45e-05"/>
    </inertial>
  </link>
  <gazebo reference="front_left_shoulder_link">
    <mu1>100000.0</mu1>
    <mu2>100000.0</mu2>
  </gazebo>
  <link name="front_left_leg_link">
    <visual>
      <geometry>
        <mesh filename="package://spotmicro_description/meshes/stl/larm.stl" scale="0.001 0.001 0.001"/>
      </geometry>
      <origin rpy="0 0 3.1416" xyz="0.134 -0.04 -0.0095"/>
      <material name="black"/>
    </visual>
    <!-- Visual cover -->
    <visual>
      <geometry>
        <mesh filename="package://spotmicro_description/meshes/stl/larm_cover.stl" scale="0.001 0.001 0.001"/>
      </geometry>
      <origin rpy="0 0 3.1416" xyz="0.134 -0.04 -0.0095"/>
      <material name="yellow"/>
    </visual>
    <collision>
      <origin xyz="0 0 -0.050"/>
      <geometry>
        <box size="0.028 0.036 0.109"/>
      </geometry>
    </collision>
    <inertial>
      <origin xyz="0 0 -0.050"/>
      <mass value="0.15"/>
      <inertia ixx="0.0001647125" ixy="0.0" ixz="0.0" iyy="0.0001583125" iyz="0.0" izz="2.6e-05"/>
    </inertial>
  </link>
  <gazebo reference="front_left_leg_link">
    <mu1>100000.0</mu1>
    <mu2>100000.0</mu2>
    <material>Gazebo/Black</material>
  </gazebo>
  <link name="front_left_foot_link">
    <visual>
      <geometry>
        <mesh filename="package://spotmicro_description/meshes/stl/lfoot.stl" scale="0.001 0.001 0.001"/>
      </geometry>
      <origin rpy="0 0 3.1416 " xyz="0.1195 -0.04 0.099"/>
      <material name="black"/>
    </visual>
    <collision>
      <geometry>
        <box size="0.026 0.02 0.08"/>
      </geometry>
      <origin xyz="0 0 -0.050"/>
    </collision>
    <inertial>
      <origin xyz="0 0 -0.050"/>
      <mass value="0.15"/>
      <inertia ixx="8.5e-05" ixy="0.0" ixz="0.0" iyy="8.845e-05" iyz="0.0" izz="1.345e-05"/>
    </inertial>
  </link>
  <gazebo reference="front_left_foot_link">
    <mu1>100000.0</mu1>
    <mu2>100000.0</mu2>
  </gazebo>
  <link name="front_left_toe_link">
    <visual>
      <geometry>
        <mesh filename="package://spotmicro_description/meshes/stl/foot.stl" scale="0.001 0.001 0.001"/>
      </geometry>
      <origin rpy="0 0.40010 0" xyz="0 -0.01 0.015"/>
      <material name="grey"/>
    </visual>
    <collision>
      <geometry>
        <sphere radius="0.02"/>
      </geometry>
    </collision>
    <inertial>
      <mass value="0.1"/>
      <origin xyz="0 0 0"/>
      <inertia ixx="1.6e-05" ixy="0.0" ixz="0.0" iyy="1.6e-05" iyz="0.0" izz="1.6e-05"/>
    </inertial>
  </link>
  <gazebo reference="front_left_toe_link">
    <minDepth>0.0002</minDepth>
    <collision name="front_left_toe_link_collision_1">
      <geometry>
        <sphere>
          <radius>0.02</radius>
        </sphere>
      </geometry>
      <surface>
        <friction>
          <ode>
            <mu>100000.0</mu>
            <mu2>100000.0</mu2>
          </ode>
          <torsional>
            <coefficient>1000000</coefficient>
            <use_patch_radius>true</use_patch_radius>
            <surface_radius>0.02</surface_radius>
            <patch_radius>0.02</patch_radius>
          </torsional>
        </friction>
      </surface>
    </collision>
  </gazebo>
  <joint name="front_left_shoulder" type="revolute">
    <parent link="base_link"/>
    <child link="front_left_shoulder_link"/>
    <axis xyz="1 0 0"/>
    <origin rpy="0 0 0" xyz="0.093 0.0395 0"/>
    <limit effort="5.0" lower="-0.548" upper="0.548" velocity="1.5"/>
    <dynamics friction="0.0"/>
  </joint>
  <transmission name="front_left_shoulder_trans">
    <type>transmission_interface/SimpleTransmission</type>
    <joint name="front_left_shoulder">
      <hardwareInterface>hardware_interface/PositionJointInterface</hardwareInterface>
    </joint>
    <actuator name="front_left_shoulder_actuator">
      <hardwareInterface>hardware_interface/PositionJointInterface</hardwareInterface>
      <mechanicalReduction>1</mechanicalReduction>
    </actuator>
  </transmission>
  <joint name="front_left_leg" type="revolute">
    <parent link="front_left_shoulder_link"/>
    <child link="front_left_leg_link"/>
    <axis xyz="0 1 0"/>
    <origin xyz="0 0.055 0"/>
    <limit effort="5.0" lower="-2.666" upper="1.548" velocity="1.5"/>
    <dynamics friction="0.0"/>
  </joint>
  <transmission name="front_left_leg_trans">
    <type>transmission_interface/SimpleTransmission</type>
    <joint name="front_left_leg">
      <hardwareInterface>hardware_interface/PositionJointInterface</hardwareInterface>
    </joint>
    <actuator name="front_left_leg_actuator">
      <hardwareInterface>hardware_interface/PositionJointInterface</hardwareInterface>
      <mechanicalReduction>1</mechanicalReduction>
    </actuator>
  </transmission>
  <joint name="front_left_foot" type="revolute">
    <parent link="front_left_leg_link"/>
    <child link="front_left_foot_link"/>
    <axis xyz="0 1 0"/>
    <origin rpy="0 0 0" xyz="0.014 0 -0.109"/>
    <limit effort="5.0" lower="-2.59" upper="0.1" velocity="1.5"/>
    <dynamics friction="0.0"/>
  </joint>
  <transmission name="front_left_foot_trans">
    <type>transmission_interface/SimpleTransmission</type>
    <joint name="front_left_foot">
      <hardwareInterface>hardware_interface/PositionJointInterface</hardwareInterface>
    </joint>
    <actuator name="front_left_foot_actuator">
      <hardwareInterface>hardware_interface/PositionJointInterface</hardwareInterface>
      <mechanicalReduction>1</mechanicalReduction>
    </actuator>
  </transmission>
  <joint name="front_left_toe" type="fixed">
    <parent link="front_left_foot_link"/>
    <child link="front_left_toe_link"/>
    <origin xyz="0 0 -0.13"/>
  </joint>
  <gazebo reference="front_left_toe">
    <provideFeedback>true</provideFeedback>
    <disableFixedJointLumping>true</disableFixedJointLumping>
  </gazebo>
  <link name="front_right_shoulder_link">
    <visual>
      <geometry>
        <mesh filename="package://spotmicro_description/meshes/stl/rshoulder.stl" scale="0.001 0.001 0.001"/>
      </geometry>
      <origin rpy="0 0 3.1416" xyz="0.135 0.0938 -0.0205"/>
      <material name="black"/>
    </visual>
    <collision>
      <geometry>
        <box size="0.044 0.038 0.07"/>
      </geometry>
    </collision>
    <inertial>
      <mass value="0.3"/>
      <origin xyz="0 0 0"/>
      <inertia ixx="0.0001586" ixy="0.0" ixz="0.0" iyy="0.0001709" iyz="0.0" izz="8.45e-05"/>
    </inertial>
  </link>
  <gazebo reference="front_right_shoulder_link">
    <mu1>100000.0</mu1>
    <mu2>100000.0</mu2>
  </gazebo>
  <link name="front_right_leg_link">
    <visual>
      <geometry>
        <mesh filename="package://spotmicro_description/meshes/stl/rarm.stl" scale="0.001 0.001 0.001"/>
      </geometry>
      <origin rpy="0 0 3.1416" xyz="0.134 0.149 -0.0095"/>
      <material name="black"/>
    </visual>
    <!-- Visual cover -->
    <visual>
      <geometry>
        <mesh filename="package://spotmicro_description/meshes/stl/rarm_cover.stl" scale="0.001 0.001 0.001"/>
      </geometry>
      <origin rpy="0 0 3.1416" xyz="0.134 0.149 -0.0095"/>
      <material name="yellow"/>
    </visual>
    <collision>
      <origin xyz="0 0 -0.050"/>
      <geometry>
        <box size="0.028 0.036 0.109"/>
      </geometry>
    </collision>
    <inertial>
      <origin xyz="0 0 -0.050"/>
      <mass value="0.15"/>
      <inertia ixx="0.0001647125" ixy="0.0" ixz="0.0" iyy="0.0001583125" iyz="0.0" izz="2.6e-05"/>
    </inertial>
  </link>
  <gazebo reference="front_right_leg_link">
    <mu1>100000.0</mu1>
    <mu2>100000.0</mu2>
    <material>Gazebo/Black</material>
  </gazebo>
  <link name="front_right_foot_link">
    <visual>
      <geometry>
        <mesh filename="package://spotmicro_description/meshes/stl/rfoot.stl" scale="0.001 0.001 0.001"/>
      </geometry>
      <origin rpy="0 0 3.1416" xyz="0.1195 0.149 0.099"/>
      <material name="black"/>
    </visual>
    <collision>
      <geometry>
        <box size="0.026 0.02 0.08"/>
      </geometry>
      <origin xyz="0 0 -0.050"/>
    </collision>
    <inertial>
      <origin xyz="0 0 -0.050"/>
      <mass value="0.15"/>
      <inertia ixx="8.5e-05" ixy="0.0" ixz="0.0" iyy="8.845e-05" iyz="0.0" izz="1.345e-05"/>
    </inertial>
  </link>
  <gazebo reference="front_right_foot_link">
    <mu1>100000.0</mu1>
    <mu2>100000.0</mu2>
  </gazebo>
  <link name="front_right_toe_link">
    <visual>
      <geometry>
        <mesh filename="package://spotmicro_description/meshes/stl/foot.stl" scale="0.001 0.001 0.001"/>
      </geometry>
      <origin rpy="0 0.40010 0" xyz="0 -0.01 0.015"/>
      <material name="grey"/>
    </visual>
    <collision>
      <geometry>
        <sphere radius="0.02"/>
      </geometry>
    </collision>
    <inertial>
      <mass value="0.1"/>
      <origin xyz="0 0 0"/>
      <inertia ixx="1.6e-05" ixy="0.0" ixz="0.0" iyy="1.6e-05" iyz="0.0" izz="1.6e-05"/>
    </inertial>
  </link>
  <gazebo reference="front_right_toe_link">
    <minDepth>0.0002</minDepth>
    <collision name="front_right_toe_link_collision_1">
      <geometry>
        <sphere>
          <radius>0.02</radius>
        </sphere>
      </geometry>
      <surface>
        <friction>
          <ode>
            <mu>100000.0</mu>
            <mu2>100000.0</mu2>
          </ode>
          <torsional>
            <coefficient>1000000</coefficient>
            <use_patch_radius>true</use_patch_radius>
            <surface_radius>0.02</surface_radius>
            <patch_radius>0.02</patch_radius>
          </torsional>
        </friction>
      </surface>
    </collision>
  </gazebo>
  <joint name="front_right_shoulder" type="revolute">
    <parent link="base_link"/>
    <child link="front_right_shoulder_link"/>
    <axis xyz="1 0 0"/>
    <origin rpy="0 0 0" xyz="0.093 -0.0395 0"/>
    <limit effort="5.0" lower="-0.548" upper="0.548" velocity="1.5"/>
    <dynamics friction="0.0"/>
  </joint>
  <transmission name="front_right_shoulder_trans">
    <type>transmission_interface/SimpleTransmission</type>
    <joint name="front_right_shoulder">
      <hardwareInterface>hardware_interface/PositionJointInterface</hardwareInterface>
    </joint>
    <actuator name="front_right_shoulder_actuator">
      <hardwareInterface>hardware_interface/PositionJointInterface</hardwareInterface>
      <mechanicalReduction>1</mechanicalReduction>
    </actuator>
  </transmission>
  <joint name="front_right_leg" type="revolute">
    <parent link="front_right_shoulder_link"/>
    <child link="front_right_leg_link"/>
    <axis xyz="0 1 0"/>
    <origin xyz="0 -0.055 0"/>
    <limit effort="5.0" lower="-2.666" upper="1.548" velocity="1.5"/>
    <dynamics friction="0.0"/>
  </joint>
  <transmission name="front_right_leg_trans">
    <type>transmission_interface/SimpleTransmission</type>
    <joint name="front_right_leg">
      <hardwareInterface>hardware_interface/PositionJointInterface</hardwareInterface>
    </joint>
    <actuator name="front_right_leg_actuator">
      <hardwareInterface>hardware_interface/PositionJointInterface</hardwareInterface>
      <mechanicalReduction>1</mechanicalReduction>
    </actuator>
  </transmission>
  <joint name="front_right_foot" type="revolute">
    <parent link="front_right_leg_link"/>
    <child link="front_right_foot_link"/>
    <axis xyz="0 1 0"/>
    <origin rpy="0 0 0" xyz="0.014 0 -0.109"/>
    <limit effort="5.0" lower="-2.59" upper="0.1" velocity="1.5"/>
    <dynamics friction="0.0"/>
  </joint>
  <transmission name="front_right_foot_trans">
    <type>transmission_interface/SimpleTransmission</type>
    <joint name="front_right_foot">
      <hardwareInterface>hardware_interface/PositionJointInterface</hardwareInterface>
    </joint>
    <actuator name="front_right_foot_actuator">
      <hardwareInterface>hardware_interface/PositionJointInterface</hardwareInterface>
      <mechanicalReduction>1</mechanicalReduction>
    </actuator>
  </transmission>
  <joint name="front_right_toe" type="fixed">
    <parent link="front_right_foot_link"/>
    <child link="front_right_toe_link"/>
    <origin xyz="0 0 -0.13"/>
  </joint>
  <gazebo reference="front_right_toe">
    <provideFeedback>true</provideFeedback>
    <disableFixedJointLumping>true</disableFixedJointLumping>
  </gazebo>
  <link name="rear_left_shoulder_link">
    <visual>
      <geometry>
        <mesh filename="package://spotmicro_description/meshes/stl/lshoulder.stl" scale="0.001 0.001 0.001"/>
      </geometry>
      <origin rpy="0 0 3.1416" xyz="0.135 0.0163 -0.0195"/>
      <material name="black"/>
    </visual>
    <collision>
      <geometry>
        <box size="0.044 0.038 0.07"/>
      </geometry>
    </collision>
    <inertial>
      <mass value="0.3"/>
      <origin xyz="0 0 0"/>
      <inertia ixx="0.0001586" ixy="0.0" ixz="0.0" iyy="0.0001709" iyz="0.0" izz="8.45e-05"/>
    </inertial>
  </link>
  <gazebo reference="rear_left_shoulder_link">
    <mu1>100000.0</mu1>
    <mu2>100000.0</mu2>
  </gazebo>
  <link name="rear_left_leg_link">
    <visual>
      <geometry>
        <mesh filename="package://spotmicro_description/meshes/stl/larm.stl" scale="0.001 0.001 0.001"/>
      </geometry>
      <origin rpy="0 0 3.1416" xyz="0.134 -0.04 -0.0095"/>
      <material name="black"/>
    </visual>
    <!-- Visual cover -->
    <visual>
      <geometry>
        <mesh filename="package://spotmicro_description/meshes/stl/larm_cover.stl" scale="0.001 0.001 0.001"/>
      </geometry>
      <origin rpy="0 0 3.1416" xyz="0.134 -0.04 -0.0095"/>
      <material name="yellow"/>
    </visual>
    <collision>
      <origin xyz="0 0 -0.050"/>
      <geometry>
        <box size="0.028 0.036 0.109"/>
      </geometry>
    </collision>
    <inertial>
      <origin xyz="0 0 -0.050"/>
      <mass value="0.15"/>
      <inertia ixx="0.0001647125" ixy="0.0" ixz="0.0" iyy="0.0001583125" iyz="0.0" izz="2.6e-05"/>
    </inertial>
  </link>
  <gazebo reference="rear_left_leg_link">
    <mu1>100000.0</mu1>
    <mu2>100000.0</mu2>
    <material>Gazebo/Black</material>
  </gazebo>
  <link name="rear_left_foot_link">
    <visual>
      <geometry>
        <mesh filename="package://spotmicro_description/meshes/stl/lfoot.stl" scale="0.001 0.001 0.001"/>
      </geometry>
      <origin rpy="0 0 3.1416 " xyz="0.1195 -0.04 0.099"/>
      <material name="black"/>
    </visual>
    <collision>
      <geometry>
        <box size="0.026 0.02 0.08"/>
      </geometry>
      <origin xyz="0 0 -0.050"/>
    </collision>
    <inertial>
      <origin xyz="0 0 -0.050"/>
      <mass value="0.15"/>
      <inertia ixx="8.5e-05" ixy="0.0" ixz="0.0" iyy="8.845e-05" iyz="0.0" izz="1.345e-05"/>
    </inertial>
  </link>
  <gazebo reference="rear_left_foot_link">
    <mu1>100000.0</mu1>
    <mu2>100000.0</mu2>
  </gazebo>
  <link name="rear_left_toe_link">
    <visual>
      <geometry>
        <mesh filename="package://spotmicro_description/meshes/stl/foot.stl" scale="0.001 0.001 0.001"/>
      </geometry>
      <origin rpy="0 0.40010 0" xyz="0 -0.01 0.015"/>
      <material name="grey"/>
    </visual>
    <collision>
      <geometry>
        <sphere radius="0.02"/>
      </geometry>
    </collision>
    <inertial>
      <mass value="0.1"/>
      <origin xyz="0 0 0"/>
      <inertia ixx="1.6e-05" ixy="0.0" ixz="0.0" iyy="1.6e-05" iyz="0.0" izz="1.6e-05"/>
    </inertial>
  </link>
  <gazebo reference="rear_left_toe_link">
    <minDepth>0.0002</minDepth>
    <collision name="rear_left_toe_link_collision_1">
      <geometry>
        <sphere>
          <radius>0.02</radius>
        </sphere>
      </geometry>
      <surface>
        <friction>
          <ode>
            <mu>100000.0</mu>
            <mu2>100000.0</mu2>
          </ode>
          <torsional>
            <coefficient>1000000</coefficient>
            <use_patch_radius>true</use_patch_radius>
            <surface_radius>0.02</surface_radius>
            <patch_radius>0.02</patch_radius>
          </torsional>
        </friction>
      </surface>
    </collision>
  </gazebo>
  <joint name="rear_left_shoulder" type="revolute">
    <parent link="base_link"/>
    <child link="rear_left_shoulder_link"/>
    <axis xyz="1 0 0"/>
    <origin rpy="0 0 0" xyz="-0.093 0.0395 0"/>
    <limit effort="5.0" lower="-0.548" upper="0.548" velocity="1.5"/>
    <dynamics friction="0.0"/>
  </joint>
  <transmission name="rear_left_shoulder_trans">
    <type>transmission_interface/SimpleTransmission</type>
    <joint name="rear_left_shoulder">
      <hardwareInterface>hardware_interface/PositionJointInterface</hardwareInterface>
    </joint>
    <actuator name="rear_left_shoulder_actuator">
      <hardwareInterface>hardware_interface/PositionJointInterface</hardwareInterface>
      <mechanicalReduction>1</mechanicalReduction>
    </actuator>
  </transmission>
  <joint name="rear_left_leg" type="revolute">
    <parent link="rear_left_shoulder_link"/>
    <child link="rear_left_leg_link"/>
    <axis xyz="0 1 0"/>
    <origin xyz="0 0.055 0"/>
    <limit effort="5.0" lower="-2.666" upper="1.548" velocity="1.5"/>
    <dynamics friction="0.0"/>
  </joint>
  <transmission name="rear_left_leg_trans">
    <type>transmission_interface/SimpleTransmission</type>
    <joint name="rear_left_leg">
      <hardwareInterface>hardware_interface/PositionJointInterface</hardwareInterface>
    </joint>
    <actuator name="rear_left_leg_actuator">
      <hardwareInterface>hardware_interface/PositionJointInterface</hardwareInterface>
      <mechanicalReduction>1</mechanicalReduction>
    </actuator>
  </transmission>
  <joint name="rear_left_foot" type="revolute">
    <parent link="rear_left_leg_link"/>
    <child link="rear_left_foot_link"/>
    <axis xyz="0 1 0"/>
    <origin rpy="0 0 0" xyz="0.014 0 -0.109"/>
    <limit effort="5.0" lower="-2.59" upper="0.1" velocity="1.5"/>
    <dynamics friction="0.0"/>
  </joint>
  <transmission name="rear_left_foot_trans">
    <type>transmission_interface/SimpleTransmission</type>
    <joint name="rear_left_foot">
      <hardwareInterface>hardware_interface/PositionJointInterface</hardwareInterface>
    </joint>
    <actuator name="rear_left_foot_actuator">
      <hardwareInterface>hardware_interface/PositionJointInterface</hardwareInterface>
      <mechanicalReduction>1</mechanicalReduction>
    </actuator>
  </transmission>
  <joint name="rear_left_toe" type="fixed">
    <parent link="rear_left_foot_link"/>
    <child link="rear_left_toe_link"/>
    <origin xyz="0 0 -0.13"/>
  </joint>
  <gazebo reference="rear_left_toe">
    <provideFeedback>true</provideFeedback>
    <disableFixedJointLumping>true</disableFixedJointLumping>
  </gazebo>
  <link name="rear_right_shoulder_link">
    <visual>
      <geometry>
        <mesh filename="package://spotmicro_description/meshes/stl/rshoulder.stl" scale="0.001 0.001 0.001"/>
      </geometry>
      <origin rpy="0 0 3.1416" xyz="0.135 0.0938 -0.0205"/>
      <material name="black"/>
    </visual>
    <collision>
      <geometry>
        <box size="0.044 0.038 0.07"/>
      </geometry>
    </collision>
    <inertial>
      <mass value="0.3"/>
      <origin xyz="0 0 0"/>
      <inertia ixx="0.0001586" ixy="0.0" ixz="0.0" iyy="0.0001709" iyz="0.0" izz="8.45e-05"/>
    </inertial>
  </link>
  <gazebo reference="rear_right_shoulder_link">
    <mu1>100000.0</mu1>
    <mu2>100000.0</mu2>
  </gazebo>
  <link name="rear_right_leg_link">
    <visual>
      <geometry>
        <mesh filename="package://spotmicro_description/meshes/stl/rarm.stl" scale="0.001 0.001 0.001"/>
      </geometry>
      <origin rpy="0 0 3.1416" xyz="0.134 0.149 -0.0095"/>
      <material name="black"/>
    </visual>
    <!-- Visual cover -->
    <visual>
      <geometry>
        <mesh filename="package://spotmicro_description/meshes/stl/rarm_cover.stl" scale="0.001 0.001 0.001"/>
      </geometry>
      <origin rpy="0 0 3.1416" xyz="0.134 0.149 -0.0095"/>
      <material name="yellow"/>
    </visual>
    <collision>
      <origin xyz="0 0 -0.050"/>
      <geometry>
        <box size="0.028 0.036 0.109"/>
      </geometry>
    </collision>
    <inertial>
      <origin xyz="0 0 -0.050"/>
      <mass value="0.15"/>
      <inertia ixx="0.0001647125" ixy="0.0" ixz="0.0" iyy="0.0001583125" iyz="0.0" izz="2.6e-05"/>
    </inertial>
  </link>
  <gazebo reference="rear_right_leg_link">
    <mu1>100000.0</mu1>
    <mu2>100000.0</mu2>
    <material>Gazebo/Black</material>
  </gazebo>
  <link name="rear_right_foot_link">
    <visual>
      <geometry>
        <mesh filename="package://spotmicro_description/meshes/stl/rfoot.stl" scale="0.001 0.001 0.001"/>
      </geometry>
      <origin rpy="0 0 3.1416" xyz="0.1195 0.149 0.099"/>
      <material name="black"/>
    </visual>
    <collision>
      <geometry>
        <box size="0.026 0.02 0.08"/>
      </geometry>
      <origin xyz="0 0 -0.050"/>
    </collision>
    <inertial>
      <origin xyz="0 0 -0.050"/>
      <mass value="0.15"/>
      <inertia ixx="8.5e-05" ixy="0.0" ixz="0.0" iyy="8.845e-05" iyz="0.0" izz="1.345e-05"/>
    </inertial>
  </link>
  <gazebo reference="rear_right_foot_link">
    <mu1>100000.0</mu1>
    <mu2>100000.0</mu2>
  </gazebo>
  <link name="rear_right_toe_link">
    <visual>
      <geometry>
        <mesh filename="package://spotmicro_description/meshes/stl/foot.stl" scale="0.001 0.001 0.001"/>
      </geometry>
      <origin rpy="0 0.40010 0" xyz="0 -0.01 0.015"/>
      <material name="grey"/>
    </visual>
    <collision>
      <geometry>
        <sphere radius="0.02"/>
      </geometry>
    </collision>
    <inertial>
      <mass value="0.1"/>
      <origin xyz="0 0 0"/>
      <inertia ixx="1.6e-05" ixy="0.0" ixz="0.0" iyy="1.6e-05" iyz="0.0" izz="1.6e-05"/>
    </inertial>
  </link>
  <gazebo reference="rear_right_toe_link">
    <minDepth>0.0002</minDepth>
    <collision name="rear_right_toe_link_collision_1">
      <geometry>
        <sphere>
          <radius>0.02</radius>
        </sphere>
      </geometry>
      <surface>
        <friction>
          <ode>
            <mu>100000.0</mu>
            <mu2>100000.0</mu2>
          </ode>
          <torsional>
            <coefficient>1000000</coefficient>
            <use_patch_radius>true</use_patch_radius>
            <surface_radius>0.02</surface_radius>
            <patch_radius>0.02</patch_radius>
          </torsional>
        </friction>
      </surface>
    </collision>
  </gazebo>
  <joint name="rear_right_shoulder" type="revolute">
    <parent link="base_link"/>
    <child link="rear_right_shoulder_link"/>
    <axis xyz="1 0 0"/>
    <origin rpy="0 0 0" xyz="-0.093 -0.0395 0"/>
    <limit effort="5.0" lower="-0.548" upper="0.548" velocity="1.5"/>
    <dynamics friction="0.0"/>
  </joint>
  <transmission name="rear_right_shoulder_trans">
    <type>transmission_interface/SimpleTransmission</type>
    <joint name="rear_right_shoulder">
      <hardwareInterface>hardware_interface/PositionJointInterface</hardwareInterface>
    </joint>
    <actuator name="rear_right_shoulder_actuator">
      <hardwareInterface>hardware_interface/PositionJointInterface</hardwareInterface>
      <mechanicalReduction>1</mechanicalReduction>
    </actuator>
  </transmission>
  <joint name="rear_right_leg" type="revolute">
    <parent link="rear_right_shoulder_link"/>
    <child link="rear_right_leg_link"/>
    <axis xyz="0 1 0"/>
    <origin xyz="0 -0.055 0"/>
    <limit effort="5.0" lower="-2.666" upper="1.548" velocity="1.5"/>
    <dynamics friction="0.0"/>
  </joint>
  <transmission name="rear_right_leg_trans">
    <type>transmission_interface/SimpleTransmission</type>
    <joint name="rear_right_leg">
      <hardwareInterface>hardware_interface/PositionJointInterface</hardwareInterface>
    </joint>
    <actuator name="rear_right_leg_actuator">
      <hardwareInterface>hardware_interface/PositionJointInterface</hardwareInterface>
      <mechanicalReduction>1</mechanicalReduction>
    </actuator>
  </transmission>
  <joint name="rear_right_foot" type="revolute">
    <parent link="rear_right_leg_link"/>
    <child link="rear_right_foot_link"/>
    <axis xyz="0 1 0"/>
    <origin rpy="0 0 0" xyz="0.014 0 -0.109"/>
    <limit effort="5.0" lower="-2.59" upper="0.1" velocity="1.5"/>
    <dynamics friction="0.0"/>
  </joint>
  <transmission name="rear_right_foot_trans">
    <type>transmission_interface/SimpleTransmission</type>
    <joint name="rear_right_foot">
      <hardwareInterface>hardware_interface/PositionJointInterface</hardwareInterface>
    </joint>
    <actuator name="rear_right_foot_actuator">
      <hardwareInterface>hardware_interface/PositionJointInterface</hardwareInterface>
      <mechanicalReduction>1</mechanicalReduction>
    </actuator>
  </transmission>
  <joint name="rear_right_toe" type="fixed">
    <parent link="rear_right_foot_link"/>
    <child link="rear_right_toe_link"/>
    <origin xyz="0 0 -0.13"/>
  </joint>
  <gazebo reference="rear_right_toe">
    <provideFeedback>true</provideFeedback>
    <disableFixedJointLumping>true</disableFixedJointLumping>
  </gazebo>
  <joint name="hokuyo_joint" type="fixed">
    <origin xyz="0 0 0.04"/>
    <parent link="base_link"/>
    <child link="hokuyo_frame"/>
  </joint>
  <link name="hokuyo_frame">
    <inertial>
      <mass value="0.270"/>
      <origin rpy="0 0 0" xyz="0 0 0"/>
      <inertia ixx="2.632e-4" ixy="0" ixz="0" iyy="2.632e-4" iyz="0" izz="1.62e-4"/>
    </inertial>
    <visual>
      <origin rpy="0 0 0" xyz="0 0 0"/>
      <geometry>
        <mesh filename="package://hector_sensors_description/meshes/hokuyo_utm30lx/hokuyo_utm_30lx.dae"/>
      </geometry>
    </visual>
    <collision>
      <origin rpy="0 0 0" xyz="0 0 -0.0115"/>
      <geometry>
        <box size="0.058 0.058 0.087"/>
        <!--<mesh filename="package://hector_sensors_description/meshes/hokuyo_utm30lx/hokuyo_utm_30lx.stl"/>-->
      </geometry>
    </collision>
  </link>
  <gazebo reference="hokuyo_frame">
    <sensor name="hokuyo" type="ray">
      <always_on>true</always_on>
      <update_rate>30</update_rate>
      <pose>0 0 0 0 0 0</pose>
      <visualize>false</visualize>
      <ray>
        <scan>
          <horizontal>
            <samples>1040</samples>
            <resolution>1</resolution>
            <min_angle>2.26892802759</min_angle>
            <max_angle>-2.26892802759</max_angle>
          </horizontal>
        </scan>
        <range>
          <min>0.2</min>
          <max>30.0</max>
          <resolution>0.01</resolution>
        </range>
        <noise>
          <type>gaussian</type>
          <mean>0.0</mean>
          <stddev>0.004</stddev>
        </noise>
      </ray>
      <plugin filename="libgazebo_ros_laser.so" name="gazebo_ros_hokuyo_controller">
        <topicName>scan</topicName>
        <frameName>hokuyo_frame</frameName>
      </plugin>
    </sensor>
  </gazebo>
  <material name="aluminum">
    <color rgba="0.5 0.5 0.5 1"/>
  </material>
  <material name="plastic">
    <color rgba="0.1 0.1 0.1 1"/>
  </material>
  <!-- camera body, with origin at bottom screw mount -->
  <joint name="d435_joint" type="fixed">
    <origin xyz="0.14 0 -0.03"/>
    <parent link="base_link"/>
    <child link="d435_bottom_screw_frame"/>
  </joint>
  <link name="d435_bottom_screw_frame"/>
  <joint name="d435_link_joint" type="fixed">
    <origin rpy="0 0 0" xyz="0.0106 0.0175 0.0125"/>
    <parent link="d435_bottom_screw_frame"/>
    <child link="d435_link"/>
  </joint>
  <link name="d435_link">
    <visual>
      <!-- the mesh origin is at front plate in between the two infrared camera axes -->
      <origin rpy="1.57079632679 0 1.57079632679" xyz="0.0043 -0.0175 0"/>
      <geometry>
        <!-- <box size="${d435_cam_width} ${d435_cam_height} ${d435_cam_depth}"/> -->
        <mesh filename="package://realsense2_description/meshes/d435.dae"/>
      </geometry>
    </visual>
    <collision>
      <origin rpy="0 0 0" xyz="0 -0.0175 0"/>
      <geometry>
        <box size="0.02505 0.09 0.025"/>
      </geometry>
    </collision>
    <inertial>
      <!-- The following are not reliable values, and should not be used for modeling -->
      <mass value="0.072"/>
      <origin xyz="0 0 0"/>
      <inertia ixx="0.003881243" ixy="0.0" ixz="0.0" iyy="0.000498940" iyz="0.0" izz="0.003879257"/>
    </inertial>
  </link>
  <!-- camera depth joints and links -->
  <joint name="d435_depth_joint" type="fixed">
    <origin rpy="0 0 0" xyz="0 0 0"/>
    <parent link="d435_link"/>
    <child link="d435_depth_frame"/>
  </joint>
  <link name="d435_depth_frame"/>
  <joint name="d435_depth_optical_joint" type="fixed">
    <origin rpy="-1.57079632679 0 -1.57079632679" xyz="0 0 0"/>
    <parent link="d435_depth_frame"/>
    <child link="d435_depth_optical_frame"/>
  </joint>
  <link name="d435_depth_optical_frame"/>
  <!-- camera left IR joints and links -->
  <joint name="d435_infra1_joint" type="fixed">
    <origin rpy="0 0 0" xyz="0 0.0 0"/>
    <parent link="d435_link"/>
    <child link="d435_infra1_frame"/>
  </joint>
  <link name="d435_infra1_frame"/>
  <joint name="d435_infra1_optical_joint" type="fixed">
    <origin rpy="-1.57079632679 0 -1.57079632679" xyz="0 0 0"/>
    <parent link="d435_infra1_frame"/>
    <child link="d435_infra1_optical_frame"/>
  </joint>
  <link name="d435_infra1_optical_frame"/>
  <!-- camera right IR joints and links -->
  <joint name="d435_infra2_joint" type="fixed">
    <origin rpy="0 0 0" xyz="0 -0.05 0"/>
    <parent link="d435_link"/>
    <child link="d435_infra2_frame"/>
  </joint>
  <link name="d435_infra2_frame"/>
  <joint name="d435_infra2_optical_joint" type="fixed">
    <origin rpy="-1.57079632679 0 -1.57079632679" xyz="0 0 0"/>
    <parent link="d435_infra2_frame"/>
    <child link="d435_infra2_optical_frame"/>
  </joint>
  <link name="d435_infra2_optical_frame"/>
  <!-- camera color joints and links -->
  <joint name="d435_color_joint" type="fixed">
    <origin rpy="0 0 0" xyz="0 0.015 0"/>
    <parent link="d435_link"/>
    <child link="d435_color_frame"/>
  </joint>
  <link name="d435_color_frame"/>
  <joint name="d435_color_optical_joint" type="fixed">
    <origin rpy="-1.57079632679 0 -1.57079632679" xyz="0 0 0"/>
    <parent link="d435_color_frame"/>
    <child link="d435_color_optical_frame"/>
  </joint>
  <link name="d435_color_optical_frame"/>
  <gazebo reference="d435_link">
    <sensor name="d435" type="depth">
      <always_on>true</always_on>
      <update_rate>0</update_rate>
      <camera>
        <horizontal_fov>1.0471975512</horizontal_fov>
        <image>
          <format>R8G8B8</format>
          <width>640</width>
          <height>480</height>
        </image>
        <clip>
          <near>0.05</near>
          <far>8.0</far>
        </clip>
      </camera>
      <plugin filename="libgazebo_ros_openni_kinect.so" name="kinect_d435_controller">
        <cameraName>d435</cameraName>
        <alwaysOn>true</alwaysOn>
        <updateRate>10.0</updateRate>
        <imageTopicName>rgb/image_rect_color</imageTopicName>
        <depthImageTopicName>depth_registered/image_raw</depthImageTopicName>
        <pointCloudTopicName>depth_registered/points</pointCloudTopicName>
        <cameraInfoTopicName>rgb/camera_info</cameraInfoTopicName>
        <depthImageCameraInfoTopicName>depth_registered/camera_info</depthImageCameraInfoTopicName>
        <frameName>d435_depth_optical_frame</frameName>
        <baseline>0.1</baseline>
        <distortion_k1>0.0</distortion_k1>
        <distortion_k2>0.0</distortion_k2>
        <distortion_k3>0.0</distortion_k3>
        <distortion_t1>0.0</distortion_t1>
        <distortion_t2>0.0</distortion_t2>
        <pointCloudCutoff>0.4</pointCloudCutoff>
      </plugin>
    </sensor>
  </gazebo>
  <!-- IMU MPU9250 -->
  <link name="imu_link">
    <inertial>
      <mass value="0.001"/>
      <origin xyz="0 0 0"/>
      <inertia ixx="1.66666666667e-10" ixy="0.0" ixz="0.0" iyy="1.66666666667e-10" iyz="0.0" izz="1.66666666667e-10"/>
    </inertial>
  </link>
  <gazebo reference="imu_link">
    <gravity>true</gravity>
    <material>Gazebo/BlueGlow</material>
  </gazebo>
  <joint name="imu_joint" type="fixed">
    <parent link="base_link"/>
    <child link="imu_link"/>
    <origin rpy="1.57 0 0" xyz="0.02 -0.04 0"/>
  </joint>
  <gazebo reference="imu_joint">
    <provideFeedback>true</provideFeedback>
    <disableFixedJointLumping>true</disableFixedJointLumping>
    <preserveFixedJoint>true</preserveFixedJoint>
  </gazebo>
  <gazebo>
    <plugin filename="libhector_gazebo_ros_imu.so" name="imu_controller">
      <updateRate>50.0</updateRate>
      <bodyName>imu_link</bodyName>
      <topicName>imu/data</topicName>
      <accelDrift>0.005 0.005 0.005</accelDrift>
      <accelGaussianNoise>0.005 0.005 0.005</accelGaussianNoise>
      <rateDrift>0.005 0.005 0.005 </rateDrift>
      <rateGaussianNoise>0.005 0.005 0.005 </rateGaussianNoise>
      <headingDrift>0.005</headingDrift>
      <headingGaussianNoise>0.005</headingGaussianNoise>
    </plugin>
  </gazebo>
  <gazebo>
    <plugin filename="libgazebo_ros_p3d.so" name="p3d_base_controller">
      <alwaysOn>true</alwaysOn>
      <updateRate>10.0</updateRate>
      <bodyName>base_link</bodyName>
      <topicName>odom/ground_truth</topicName>
      <gaussianNoise>0.01</gaussianNoise>
      <frameName>world</frameName>
      <xyzOffsets>0 0 0</xyzOffsets>
      <rpyOffsets>0 0 0</rpyOffsets>
    </plugin>
  </gazebo>
  <gazebo>
    <plugin filename="libgazebo_ros_control.so" name="gazebo_ros_control">
      <legacyModeNS>true</legacyModeNS>
    </plugin>
  </gazebo>
</robot>

